<?xml version="1.0" encoding="utf-8"?>
<!-- This URDF was automatically created by SolidWorks to URDF Exporter! Originally created by Stephen Brawner (brawner@gmail.com) 
     Commit Version: 1.5.1-0-g916b5db  Build Version: 1.5.7152.31018
     For more information, please see http://wiki.ros.org/sw_urdf_exporter -->
<robot
  name="three_links">
  <link
    name="base_link">
    <inertial>
      <origin
        xyz="-9.74542958129844E-19 0 0.03"
        rpy="0 0 0" />
      <mass
        value="0.471238898038469" />
      <inertia
        ixx="0.000435895980685584"
        ixy="0"
        ixz="-1.52551870759393E-36"
        iyy="0.000435895980685584"
        iyz="-1.36598121004842E-36"
        izz="0.000589048622548086" />
    </inertial>
    <visual>
      <origin
        xyz="0 0 0"
        rpy="0 0 0" />
      <geometry>
        <mesh
          filename="package://three_links/meshes/base_link.STL" />
      </geometry>
      <material
        name="">
        <color
          rgba="0.792156862745098 0.819607843137255 0.933333333333333 1" />
      </material>
    </visual>
    <collision>
      <origin
        xyz="0 0 0"
        rpy="0 0 0" />
      <geometry>
        <mesh
          filename="package://three_links/meshes/base_link.STL" />
      </geometry>
    </collision>
  </link>
  <link
    name="Link1">
    <inertial>
      <origin
        xyz="0.0913956355205956 -1.59622753367511E-18 0.005"
        rpy="0 0 0" />
      <mass
        value="0.13473452545241" />
      <inertia
        ixx="7.37451150071335E-05"
        ixy="-1.52859105184074E-20"
        ixz="-1.66880107710191E-21"
        iyy="0.00103353948460889"
        iyz="4.48504911956552E-22"
        izz="0.00110503902419182" />
    </inertial>
    <visual>
      <origin
        xyz="0 0 0"
        rpy="0 0 0" />
      <geometry>
        <mesh
          filename="package://three_links/meshes/Link1.STL" />
      </geometry>
      <material
        name="">
        <color
          rgba="0.792156862745098 0.819607843137255 0.933333333333333 1" />
      </material>
    </visual>
    <collision>
      <origin
        xyz="0 0 0"
        rpy="0 0 0" />
      <geometry>
        <mesh
          filename="package://three_links/meshes/Link1.STL" />
      </geometry>
    </collision>
  </link>
  <joint
    name="Joint1"
    type="revolute">
    <origin
      xyz="0 0 0.06"
      rpy="0 0 0" />
    <parent
      link="base_link" />
    <child
      link="Link1" />
    <axis
      xyz="0 0 1" />
    <limit
      lower="-3.14"
      upper="3.14"
      effort="0"
      velocity="0" />
  </joint>
  <link
    name="Link2">
    <inertial>
      <origin
        xyz="0.090869161726064 3.21554892524242E-18 0.005"
        rpy="0 0 0" />
      <mass
        value="0.110747393273271" />
      <inertia
        ixx="4.77883358034583E-05"
        ixy="-1.31010091129641E-20"
        ixz="-1.3163636453894E-21"
        iyy="0.000799779347162625"
        iyz="-7.81927896001231E-23"
        izz="0.000845721893078195" />
    </inertial>
    <visual>
      <origin
        xyz="0 0 0"
        rpy="0 0 0" />
      <geometry>
        <mesh
          filename="package://three_links/meshes/Link2.STL" />
      </geometry>
      <material
        name="">
        <color
          rgba="0.792156862745098 0.819607843137255 0.933333333333333 1" />
      </material>
    </visual>
    <collision>
      <origin
        xyz="0 0 0"
        rpy="0 0 0" />
      <geometry>
        <mesh
          filename="package://three_links/meshes/Link2.STL" />
      </geometry>
    </collision>
  </link>
  <joint
    name="Joint2"
    type="revolute">
    <origin
      xyz="0.2 0 0.01"
      rpy="0 0 0" />
    <parent
      link="Link1" />
    <child
      link="Link2" />
    <axis
      xyz="0 0 1" />
    <limit
      lower="-3.14"
      upper="3.14"
      effort="0"
      velocity="0" />
  </joint>
  <link
    name="Link3">
    <inertial>
      <origin
        xyz="0.0756376742620836 1.24407015031345E-18 0.00499999999999999"
        rpy="0 0 0" />
      <mass
        value="0.0769154803979707" />
      <inertia
        ixx="2.30997386339273E-05"
        ixy="4.25848211964126E-21"
        ixz="3.63843143388111E-21"
        iyy="0.000449559139082496"
        iyz="2.82429819271251E-22"
        izz="0.000471376953043124" />
    </inertial>
    <visual>
      <origin
        xyz="0 0 0"
        rpy="0 0 0" />
      <geometry>
        <mesh
          filename="package://three_links/meshes/Link3.STL" />
      </geometry>
      <material
        name="">
        <color
          rgba="0.792156862745098 0.819607843137255 0.933333333333333 1" />
      </material>
    </visual>
    <collision>
      <origin
        xyz="0 0 0"
        rpy="0 0 0" />
      <geometry>
        <mesh
          filename="package://three_links/meshes/Link3.STL" />
      </geometry>
    </collision>
  </link>
  <joint
    name="Joint3"
    type="revolute">
    <origin
      xyz="0.2 0 0.01"
      rpy="0 0 0" />
    <parent
      link="Link2" />
    <child
      link="Link3" />
    <axis
      xyz="0 0 1" />
    <limit
      lower="-3.14"
      upper="3.14"
      effort="0"
      velocity="0" />
  </joint>
  <link
    name="gripper">
    <inertial>
      <origin
        xyz="1.11022302462516E-16 -2.41558513055394E-35 -0.000988372093023257"
        rpy="0 0 0" />
      <mass
        value="0.0168860605130451" />
      <inertia
        ixx="2.36996939984108E-06"
        ixy="1.80997399548307E-39"
        ixz="9.03298934946049E-23"
        iyy="2.36996939984108E-06"
        iyz="-6.89630791461946E-39"
        izz="1.50698272601885E-06" />
    </inertial>
    <visual>
      <origin
        xyz="0 0 0"
        rpy="0 0 0" />
      <geometry>
        <mesh
          filename="package://three_links/meshes/gripper.STL" />
      </geometry>
      <material
        name="">
        <color
          rgba="0.792156862745098 0.819607843137255 0.933333333333333 1" />
      </material>
    </visual>
    <collision>
      <origin
        xyz="0 0 0"
        rpy="0 0 0" />
      <geometry>
        <mesh
          filename="package://three_links/meshes/gripper.STL" />
      </geometry>
    </collision>
  </link>
  <joint
    name="gripper"
    type="fixed">
    <origin
      xyz="0.2 0 0"
      rpy="0 0 0" />
    <parent
      link="Link3" />
    <child
      link="gripper" />
    <axis
      xyz="0 0 0" />
  </joint>
</robot>